<?xml version="1.0" encoding="utf-8"?>
<!-- =================================================================================== -->
<!-- |    This document was autogenerated by xacro from SCARA.xacro                    | -->
<!-- |    EDITING THIS FILE BY HAND IS NOT RECOMMENDED                                 | -->
<!-- =================================================================================== -->
<robot name="SCARA">
  <material name="blue">
    <color rgba="0 0 0.8 1"/>
  </material>
  <material name="white">
    <color rgba="1 1 1 1"/>
  </material>
  <material name="green">
    <color rgba="0 1 0 1"/>
  </material>
  <material name="red">
    <color rgba="1 0 0 1"/>
  </material>
  <link name="base_link">
    <visual>
      <geometry>
        <cylinder length="0.3" radius="0.15"/>
      </geometry>
      <material name="blue"/>
    </visual>
  </link>
  <link name="link_1">
    <visual>
      <geometry>
        <cylinder length="0.5" radius="0.1"/>
      </geometry>
      <material name="white"/>
      <origin rpy="-1.57075 0 0" xyz="0 0.25 0.15"/>
    </visual>
  </link>
  <joint name="joint_1" type="revolute">
    <visual>
      <geometry>
        <cylinder length="0.5" radius="0.1"/>
      </geometry>
      <material name="white"/>
      <origin rpy="-1.57075 0 0" xyz="0 0.25 0.15"/>
    </visual>
    <axis xyz="0 0 1"/>
    <limit effort="1000.0" lower="-3.14" upper="3.14" velocity="0.5"/>
    <origin rpy="0 0 0" xyz="0 0 0.15"/>
    <parent link="base_link"/>
    <child link="link_1"/>
  </joint>
  <link name="link_2">
    <visual>
      <geometry>
        <cylinder length="0.5" radius="0.1"/>
      </geometry>
      <material name="red"/>
      <origin rpy="-1.57075 0 0" xyz="0 0.25 0.15"/>
    </visual>
  </link>
  <joint name="joint_2" type="revolute">
    <axis xyz="0 0 1"/>
    <limit effort="1000.0" lower="-3.14" upper="3.14" velocity="0.5"/>
    <parent link="link_1"/>
    <child link="link_2"/>
    <origin xyz="0 0.5 0 "/>
  </joint>
  <link name="link_3">
    <visual>
      <geometry>
        <cylinder length="0.2" radius="0.1"/>
      </geometry>
      <material name="white"/>
      <origin rpy="0 0 0" xyz="0 0 0.15"/>
    </visual>
  </link>
  <joint name="joint_3" type="revolute">
    <axis xyz="0 0 1"/>
    <limit effort="1000.0" lower="-3.14" upper="3.14" velocity="0.5"/>
    <parent link="link_2"/>
    <child link="link_3"/>
    <origin xyz="0 0.5 0 "/>
  </joint>
  <link name="link_4">
    <visual>
      <geometry>
        <cylinder length="0.4" radius="0.05"/>
      </geometry>
      <material name="red"/>
      <origin rpy="0 0 0" xyz="0 0 0.15"/>
    </visual>
  </link>
  <joint name="joint_4" type="prismatic">
    <parent link="link_3"/>
    <child link="link_4"/>
    <axis xyz="0 0 1"/>
    <limit effort="1000.0" lower="-0.2" upper="0.2" velocity="0.5"/>
    <origin xyz="0 0 0 "/>
  </joint>
  <link name="EndEffector">
    <visual>
      <geometry>
        <box size="0.05 0.1 0.03"/>
      </geometry>
      <material name="green"/>
      <origin rpy="0 0 0" xyz="0 0 -0.05"/>
    </visual>
  </link>
  <joint name="joint_5" type="fixed">
    <parent link="link_4"/>
    <child link="EndEffector"/>
    <origin rpy="0 0 0" xyz="0 0 0"/>
  </joint>
</robot>

